Workbook

Sheet Exp
A1: NEXT MEDIA
A2: PLOT 13, SUMMIT VIEW ROAD
A3: P.O BOX 7613
A4: EXPENSE ALLOWANCES FOR THE MONTH ENDED 15 JULY, 2026 | E4: .
B7: Name | C7: Position | D7: Expense Allowance | E7: SACCO | F7: Food | G7: Medicare | H7: Hire purchase | I7: Cost share | J7: ID Replacement | K7: Fuel/Advance | L7: Net Expense Allowance
A8: 1 | B8: Aaron Magulu | C8: Stores | L8: =D8-E8-F8-G8-H8-I8-J8-K8 -> 0 | M8: =E8+F8+G8+H8+I8+J8+K8+L8 -> 0 | N8: =D8-M8 -> 0
A9: 2 | B9: Abdallah Gulemye | C9: Content Officer | L9: =D9-E9-F9-G9-H9-I9-J9-K9 -> 0 | M9: =E9+F9+G9+H9+I9+J9+K9+L9 -> 0 | N9: =D9-M9 -> 0
A10: 3 | B10: Abdallah Magumba | C10: Current Affairs Director | L10: =D10-E10-F10-G10-H10-I10-J10-K10 -> 0 | M10: =E10+F10+G10+H10+I10+J10+K10+L10 -> 0 | N10: =D10-M10 -> 0
A11: 4 | B11: Abdul Majid Mugisa | C11: Content Officer | L11: =D11-E11-F11-G11-H11-I11-J11-K11 -> 0 | M11: =E11+F11+G11+H11+I11+J11+K11+L11 -> 0 | N11: =D11-M11 -> 0
A12: 5 | B12: Abubaker Lubwama | C12: SM Resources | L12: =D12-E12-F12-G12-H12-I12-J12-K12 -> 0 | M12: =E12+F12+G12+H12+I12+J12+K12+L12 -> 0 | N12: =D12-M12 -> 0
A13: 6 | B13: Adam Mayambala | C13: News Reporter | L13: =D13-E13-F13-G13-H13-I13-J13-K13 -> 0 | M13: =E13+F13+G13+H13+I13+J13+K13+L13 -> 0 | N13: =D13-M13 -> 0
A14: 7 | B14: Adrian Bakuwama | C14: Content Officer | L14: =D14-E14-F14-G14-H14-I14-J14-K14 -> 0 | M14: =E14+F14+G14+H14+I14+J14+K14+L14 -> 0 | N14: =D14-M14 -> 0
A15: 8 | B15: Aggrey Waguma | C15: Studio Cameraperson | L15: =D15-E15-F15-G15-H15-I15-J15-K15 -> 0 | M15: =E15+F15+G15+H15+I15+J15+K15+L15 -> 0 | N15: =D15-M15 -> 0
A16: 9 | B16: Ahmed Sultan Buyungo | C16: Video Editor/Producer | L16: =D16-E16-F16-G16-H16-I16-J16-K16 -> 0 | M16: =E16+F16+G16+H16+I16+J16+K16+L16 -> 0 | N16: =D16-M16 -> 0
A17: 10 | B17: Aisha Komugisha | C17: Payable Accountant | L17: =D17-E17-F17-G17-H17-I17-J17-K17 -> 0 | M17: =E17+F17+G17+H17+I17+J17+K17+L17 -> 0 | N17: =D17-M17 -> 0
A18: 11 | B18: Alex Mugasha | C18: Bureau Chief-Mbarara | L18: =D18-E18-F18-G18-H18-I18-J18-K18 -> 0 | M18: =E18+F18+G18+H18+I18+J18+K18+L18 -> 0 | N18: =D18-M18 -> 0
A19: 12 | B19: Alex Ssentongo | C19: Video Editor | L19: =D19-E19-F19-G19-H19-I19-J19-K19 -> 0 | M19: =E19+F19+G19+H19+I19+J19+K19+L19 -> 0 | N19: =D19-M19 -> 0
... A26: 19 | B26: Baker Zenah | C26: Head of Content Production | L26: =D26-E26-F26-G26-H26-I26-J26-K26 -> 0 | M26: =E26+F26+G26+H26+I26+J26+K26+L26 -> 0 | N26: =D26-M26 -> 0
A27: 20 | B27: Balinda Immam | L27: =D27-E27-F27-G27-H27-I27-J27-K27 -> 0 | M27: =E27+F27+G27+H27+I27+J27+K27+L27 -> 0 | N27: =D27-M27 -> 0
A28: 21 | B28: Ben Mwine | C28: HOC&P | L28: =D28-E28-F28-G28-H28-I28-J28-K28 -> 0 | M28: =E28+F28+G28+H28+I28+J28+K28+L28 -> 0 | N28: =D28-M28 -> 0
A29: 22 | B29: Benson Ongom | C29: Bureau Chief | L29: =D29-E29-F29-G29-H29-I29-J29-K29 -> 0 | M29: =E29+F29+G29+H29+I29+J29+K29+L29 -> 0 | N29: =D29-M29 -> 0
A30: 23 | B30: Betty Kayenga | C30: Payable Accountant | L30: =D30-E30-F30-G30-H30-I30-J30-K30 -> 0 | M30: =E30+F30+G30+H30+I30+J30+K30+L30 -> 0 | N30: =D30-M30 -> 0
A31: 24 | B31: Boman Bigirwenkya | C31: Head of Finance | L31: =D31-E31-F31-G31-H31-I31-J31-K31 -> 0 | M31: =E31+F31+G31+H31+I31+J31+K31+L31 -> 0 | N31: =D31-M31 -> 0
A32: 25 | B32: Bosco Afasha | C32: Driver | L32: =D32-E32-F32-G32-H32-I32-J32-K32 -> 0 | M32: =E32+F32+G32+H32+I32+J32+K32+L32 -> 0 | N32: =D32-M32 -> 0
A33: 26 | B33: Bridget Nsimenta | C33: Bureau Reporter- Mbarara | L33: =D33-E33-F33-G33-H33-I33-J33-K33 -> 0 | M33: =E33+F33+G33+H33+I33+J33+K33+L33 -> 0 | N33: =D33-M33 -> 0
A34: 27 | B34: Calvin Mugume | C34: CFO | L34: =D34-E34-F34-G34-H34-I34-J34-K34 -> 0 | M34: =E34+F34+G34+H34+I34+J34+K34+L34 -> 0 | N34: =D34-M34 -> 0
A35: 28 | B35: Canary Mugume | C35: News Anchor | L35: =D35-E35-F35-G35-H35-I35-J35-K35 -> 0 | M35: =E35+F35+G35+H35+I35+J35+K35+L35 -> 0 | N35: =D35-M35 -> 0
A36: 29 | B36: Catherine Nakato | C36: Reporter | L36: =D36-E36-F36-G36-H36-I36-J36-K36 -> 0 | M36: =E36+F36+G36+H36+I36+J36+K36+L36 -> 0 | N36: =D36-M36 -> 0
A37: 30 | B37: Crish Semanda | L37: =D37-E37-F37-G37-H37-I37-J37-K37 -> 0 | M37: =E37+F37+G37+H37+I37+J37+K37+L37 -> 0 | N37: =D37-M37 -> 0
A38: 31 | B38: Christopher Lutwama | C38: Content Manager Officer | L38: =D38-E38-F38-G38-H38-I38-J38-K38 -> 0 | M38: =E38+F38+G38+H38+I38+J38+K38+L38 -> 0 | N38: =D38-M38 -> 0
A39: 32 | B39: Christopher Wanobere | C39: GM Broadcast | L39: =D39-E39-F39-G39-H39-I39-J39-K39 -> 0 | M39: =E39+F39+G39+H39+I39+J39+K39+L39 -> 0 | N39: =D39-M39 -> 0
A40: 33 | B40: Dalton Kaweesa | C40: Head of Current Affairs | L40: =D40-E40-F40-G40-H40-I40-J40-K40 -> 0 | M40: =E40+F40+G40+H40+I40+J40+K40+L40 -> 0 | N40: =D40-M40 -> 0
A41: 34 | B41: Dan Ayebare | C41: News Reporter | L41: =D41-E41-F41-G41-H41-I41-J41-K41 -> 0 | M41: =E41+F41+G41+H41+I41+J41+K41+L41 -> 0 | N41: =D41-M41 -> 0
A42: 35 | B42: David Ochieng | C42: Bureau Chief - Bukedi | L42: =D42-E42-F42-G42-H42-I42-J42-K42 -> 0 | M42: =E42+F42+G42+H42+I42+J42+K42+L42 -> 0 | N42: =D42-M42 -> 0
A43: 36 | B43: Dennis Ibanda Mugulusi | C43: Cameraperson | L43: =D43-E43-F43-G43-H43-I43-J43-K43 -> 0 | M43: =E43+F43+G43+H43+I43+J43+K43+L43 -> 0 | N43: =D43-M43 -> 0
A44: 37 | B44: Derrick Kyambadde | C44: Video Editor | L44: =D44-E44-F44-G44-H44-I44-J44-K44 -> 0 | M44: =E44+F44+G44+H44+I44+J44+K44+L44 -> 0 | N44: =D44-M44 -> 0
A45: 38 | B45: Derrick Ssemwogerere henry | C45: Studio Cameraperson | L45: =D45-E45-F45-G45-H45-I45-J45-K45 -> 0 | M45: =E45+F45+G45+H45+I45+J45+K45+L45 -> 0 | N45: =D45-M45 -> 0
A46: 39 | B46: Desire Derekford Mugumisa | C46: HOCA | L46: =D46-E46-F46-G46-H46-I46-J46-K46 -> 0 | M46: =E46+F46+G46+H46+I46+J46+K46+L46 -> 0 | N46: =D46-M46 -> 0
A47: 40 | B47: Dorah Atwongyeire | C47: Head of Multi media | L47: =D47-E47-F47-G47-H47-I47-J47-K47 -> 0 | M47: =E47+F47+G47+H47+I47+J47+K47+L47 -> 0 | N47: =D47-M47 -> 0
A48: 41 | B48: Edgar Mathew Karuhanga | C48: News Reporter | L48: =D48-E48-F48-G48-H48-I48-J48-K48 -> 0 | M48: =E48+F48+G48+H48+I48+J48+K48+L48 -> 0 | N48: =D48-M48 -> 0
...

Sheet Salary
B1: NEXT MEDIA
B2: PLOT 13 SUMMIT VIEW ROAD
B3: P.O BOX 7613
B4: PAYROLL FOR THE MONTH ENDED 27 JULY, 2026 | J4: .
A7: ID No | B7: Name | C7: Position | D7: Salary | E7: Gross Pay | F7: PAYE | G7: NSSF 10% | H7: NSSF 5% | I7: Total Deduction | J7: SACCO | K7: Food | L7: Medicare | M7: Hire purchase | N7: Cost share | O7: ID Replacement | P7: Penalty | Q7: Net Pay
B8: NBS
A9: 903/20 | B9: Aaron Magulu | C9: Grip and Stage | Q9: =E9-I9-J9-K9-L9-M9-N9-O9-P9 -> 0 | R9: =J9+K9+L9+M9+N9+O9+P9+Q9 -> 0 | S9: =D9-R9 -> 0
A10: 743/20 | B10: Abdallah Magumba | C10: Transmission | Q10: =E10-I10-J10-K10-L10-M10-N10-O10-P10 -> 0 | R10: =J10+K10+L10+M10+N10+O10+P10+Q10 -> 0 | S10: =D10-R10 -> 0
A11: 714/20 | B11: Abdallar Gulemye | C11: Content Officer | Q11: =E11-I11-J11-K11-L11-M11-N11-O11-P11 -> 0 | R11: =J11+K11+L11+M11+N11+O11+P11+Q11 -> 0 | S11: =D11-R11 -> 0
A12: 769/20 | B12: Abdul Majid Mugisa | C12: Content Officer | Q12: =E12-I12-J12-K12-L12-M12-N12-O12-P12 -> 0 | R12: =J12+K12+L12+M12+N12+O12+P12+Q12 -> 0 | S12: =D12-R12 -> 0
A13: 051/20 | B13: Abubaker Lubwama | C13: Ass Stores | Q13: =E13-I13-J13-K13-L13-M13-N13-O13-P13 -> 0 | R13: =J13+K13+L13+M13+N13+O13+P13+Q13 -> 0 | S13: =D13-R13 -> 0
A14: 683/20 | B14: Adam Mayambala | C14: News Reporter | Q14: =E14-I14-J14-K14-L14-M14-N14-O14-P14 -> 0 | R14: =J14+K14+L14+M14+N14+O14+P14+Q14 -> 0 | S14: =D14-R14 -> 0
A15: 768/20 | B15: Adrian Bakuwamma | C15: Content Officer | Q15: =E15-I15-J15-K15-L15-M15-N15-O15-P15 -> 0 | R15: =J15+K15+L15+M15+N15+O15+P15+Q15 -> 0 | S15: =D15-R15 -> 0
A16: 086/20 | B16: Aggrey Waguma | C16: Camera Man | Q16: =E16-I16-J16-K16-L16-M16-N16-O16-P16 -> 0 | R16: =J16+K16+L16+M16+N16+O16+P16+Q16 -> 0 | S16: =D16-R16 -> 0
A17: 467/20 | B17: Ahmed Sultan Buyungo | C17: Video Editor | Q17: =E17-I17-J17-K17-L17-M17-N17-O17-P17 -> 0 | R17: =J17+K17+L17+M17+N17+O17+P17+Q17 -> 0 | S17: =D17-R17 -> 0
A18: 924/20 | B18: Aisha Komugisha | C18: Payable Accountant | Q18: =E18-I18-J18-K18-L18-M18-N18-O18-P18 -> 0 | R18: =J18+K18+L18+M18+N18+O18+P18+Q18 -> 0 | S18: =D18-R18 -> 0
A19: 710/20 | B19: Alan John Mwesigwa | C19: Bureau chief bunyoro | Q19: =E19-I19-J19-K19-L19-M19-N19-O19-P19 -> 0 | R19: =J19+K19+L19+M19+N19+O19+P19+Q19 -> 0 | S19: =D19-R19 -> 0
A20: 093/20 | B20: Allan Mark Kiberu | C20: Transmission | Q20: =E20-I20-J20-K20-L20-M20-N20-O20-P20 -> 0 | R20: =J20+K20+L20+M20+N20+O20+P20+Q20 -> 0 | S20: =D20-R20 -> 0
... A112: 966/20 | B112: Jimmy Okech | C112: Cameraperson | Q112: =E112-I112-J112-K112-L112-M112-N112-O112-P112 -> 0 | R112: =J112+K112+L112+M112+N112+O112+P112+Q112 -> 0 | S112: =D112-R112 -> 0
B113: Joan Umutesi | C113: Stylist | Q113: =E113-I113-J113-K113-L113-M113-N113-O113-P113 -> 0 | R113: =J113+K113+L113+M113+N113+O113+P113+Q113 -> 0 | S113: =D113-R113 -> 0
A114: 908/20 | B114: Joel Ssali | C114: Tansmission Officer | Q114: =E114-I114-J114-K114-L114-M114-N114-O114-P114 -> 0 | R114: =J114+K114+L114+M114+N114+O114+P114+Q114 -> 0 | S114: =D114-R114 -> 0
A115: 572/20 | B115: John Paul Kiwanuka | C115: Cameraperson | Q115: =E115-I115-J115-K115-L115-M115-N115-O115-P115 -> 0 | R115: =J115+K115+L115+M115+N115+O115+P115+Q115 -> 0 | S115: =D115-R115 -> 0
A116: 463/20 | B116: Joseph Makumbi | C116: Cameraperson | Q116: =E116-I116-J116-K116-L116-M116-N116-O116-P116 -> 0 | R116: =J116+K116+L116+M116+N116+O116+P116+Q116 -> 0 | S116: =D116-R116 -> 0
A117: 197/20 | B117: Joseph Mawanda | C117: Driver | Q117: =E117-I117-J117-K117-L117-M117-N117-O117-P117 -> 0 | R117: =J117+K117+L117+M117+N117+O117+P117+Q117 -> 0 | S117: =D117-R117 -> 0
A118: 709/20 | B118: Joseph Omagor | C118: Bureau chief Gulu | Q118: =E118-I118-J118-K118-L118-M118-N118-O118-P118 -> 0 | R118: =J118+K118+L118+M118+N118+O118+P118+Q118 -> 0 | S118: =D118-R118 -> 0
A119: 388/20 | B119: Joseph Rwanguhayo | C119: Cameraperson | Q119: =E119-I119-J119-K119-L119-M119-N119-O119-P119 -> 0 | R119: =J119+K119+L119+M119+N119+O119+P119+Q119 -> 0 | S119: =D119-R119 -> 0
A120: 198/20 | B120: Joseph Turyagumanawe | C120: Transmission Ass | Q120: =E120-I120-J120-K120-L120-M120-N120-O120-P120 -> 0 | R120: =J120+K120+L120+M120+N120+O120+P120+Q120 -> 0 | S120: =D120-R120 -> 0
A121: 199/20 | B121: Josephat Walugembe | C121: News Producer | Q121: =E121-I121-J121-K121-L121-M121-N121-O121-P121 -> 0 | R121: =J121+K121+L121+M121+N121+O121+P121+Q121 -> 0 | S121: =D121-R121 -> 0
A122: 588/20 | B122: Joshua Kakeeto | C122: Cameraperson | Q122: =E122-I122-J122-K122-L122-M122-N122-O122-P122 -> 0 | R122: =J122+K122+L122+M122+N122+O122+P122+Q122 -> 0 | S122: =D122-R122 -> 0
A123: 201/20 | B123: Joshua Mujunga | C123: Video Journalist | Q123: =E123-I123-J123-K123-L123-M123-N123-O123-P123 -> 0 | R123: =J123+K123+L123+M123+N123+O123+P123+Q123 -> 0 | S123: =D123-R123 -> 0
A124: 718/20 | B124: Joshua Rwamura | C124: Cameraperson | Q124: =E124-I124-J124-K124-L124-M124-N124-O124-P124 -> 0 | R124: =J124+K124+L124+M124+N124+O124+P124+Q124 -> 0 | S124: =D124-R124 -> 0
A125: 964/20 | B125: Joshua Wavamuno | C125: Cameraperson | Q125: =E125-I125-J125-K125-L125-M125-N125-O125-P125 -> 0 | R125: =J125+K125+L125+M125+N125+O125+P125+Q125 -> 0 | S125: =D125-R125 -> 0
... A156: 236/20 | B156: Moses Katumba | C156: Driver | Q156: =E156-I156-J156-K156-L156-M156-N156-O156-P156 -> 0 | R156: =J156+K156+L156+M156+N156+O156+P156+Q156 -> 0 | S156: =D156-R156 -> 0
A157: 237/20 | B157: Moses Namayo | Q157: =E157-I157-J157-K157-L157-M157-N157-O157-P157 -> 0 | R157: =J157+K157+L157+M157+N157+O157+P157+Q157 -> 0 | S157: =D157-R157 -> 0
A158: 037/20 | B158: Moses Oyoma | C158: Head Sales | Q158: =E158-I158-J158-K158-L158-M158-N158-O158-P158 -> 0 | R158: =J158+K158+L158+M158+N158+O158+P158+Q158 -> 0 | S158: =D158-R158 -> 0
A159: 717/20 | B159: Muhammad Mutatiina | C159: Video Journalist | Q159: =E159-I159-J159-K159-L159-M159-N159-O159-P159 -> 0 | R159: =J159+K159+L159+M159+N159+O159+P159+Q159 -> 0 | S159: =D159-R159 -> 0
A160: 233/20 | B160: Muhsin Kaliisa | C160: Cameran | Q160: =E160-I160-J160-K160-L160-M160-N160-O160-P160 -> 0 | R160: =J160+K160+L160+M160+N160+O160+P160+Q160 -> 0 | S160: =D160-R160 -> 0
A161: 242/20 | B161: Mwasit Kaudha | C161: Asst. Admin | Q161: =E161-I161-J161-K161-L161-M161-N161-O161-P161 -> 0 | R161: =J161+K161+L161+M161+N161+O161+P161+Q161 -> 0 | S161: =D161-R161 -> 0
A162: 244/20 | B162: Nelson Babyale | C162: Deputy Head of Eng news | Q162: =E162-I162-J162-K162-L162-M162-N162-O162-P162 -> 0 | R162: =J162+K162+L162+M162+N162+O162+P162+Q162 -> 0 | S162: =D162-R162 -> 0
A163: 489/20 | B163: Nina Kakwanzi | C163: Show Host | Q163: =E163-I163-J163-K163-L163-M163-N163-O163-P163 -> 0 | R163: =J163+K163+L163+M163+N163+O163+P163+Q163 -> 0 | S163: =D163-R163 -> 0
...

Sheet Bank Exp Allowance
B1: NBS
B2: S/No. | C2: Name | E2: Saving Account No. | F2: Amount
B3: 1 | C3: Kaudha Mwasit | E3: 1013011661297 | F3: =+Exp!L107 -> 0
B4: 2 | C4: Salmah Namwanje | E4: 1013011937394 | F4: =+Exp!L152 -> 0
B5: 3 | C5: Richard Olwenyi | E5: 1151152915113 | F5: =+Exp!L149 -> 0
B6: 4 | C6: Semwogerere Derick | E6: 01073044211710 | F6: =+Exp!L45 -> 0
B7: 5 | C7: Ibanda Samuel | E7: 01493014713209 | F7: =+Exp!L77 -> 0
B8: 6 | C8: Isaac Mubuka | E8: 01063089038015 | F8: =+Exp!L82 -> 0
B9: 7 | C9: Joseph Mawanda | E9: 01063089095825 | F9: =+Exp!L95 -> 0
B10: 8 | C10: Irene Constance Namajja | E10: 01063089069431 | F10: =+Exp!L133 -> 0
B11: 9 | C11: Isima Isiko | E11: 01063089037812 | F11: =+Exp!L85 -> 0
B12: 10 | C12: Katumba Moses | E12: 01513089227682 | F12: =+Exp!L106 -> 0
B13: 11 | C13: Alex Mugasha | E13: 01081157877128 | F13: =+Exp!L18 -> 0
B14: 12 | C14: Brian Tukasingura | E14: 01421000215916 | F14: =+Exp!L182 -> 0
B15: 13 | C15: Ayamo Ruth Eyobu | E15: 01081099698765 | F15: =+Exp!L24 -> 0
B16: 14 | C16: Timothy Maganda | E16: 01221151480319 | F16: =+Exp!L166 -> 0
B17: 15 | C17: Badru Kasirye | E17: 01063089284508 | F17: =+Exp!L25 -> 0
B18: 16 | C18: Kyomu Henry | E18: 1063013376621 | F18: =+Exp!L75 -> 0
B19: 18 | C19: Henry Mugenyi | E19: 01070010802519 | F19: =+Exp!L76 -> 0
B20: 19 | C20: Kitimbo Thomas | E20: 01440011974888 | F20: =+Exp!L110 -> 0
B21: 20 | C21: Kenneth Kaweesa | E21: 01060012126804 | F21: =+Exp!L108 -> 0
B22: 21 | C22: Kiwanuka John Paul | E22: 01070012330676 | F22: =+Exp!L93 -> 0
B23: 22 | C23: Magembe Farish | E23: 01030012235582 | F23: =+Exp!L56 -> 0
B24: 23 | C24: Joseph Omagor | E24: 01981131213490 | F24: =+Exp!L96 -> 0
B25: 24 | C25: Agrey Waguma | E25: 01070014050534 | F25: =+Exp!L15 -> 0
B26: 25 | C26: Wasswa Hassan Mutebi | E26: 01070010885253 | F26: =+Exp!L72 -> 0
B27: 26 | C27: Dennis Ibanda | E27: 01070014676345 | F27: =+Exp!L43 -> 0
B28: 27 | C28: Jamila Mulindwa Namuyiga | E28: 01010014546860 | F28: =+Exp!L90 -> 0
B29: 28 | C29: Paul Kayonga | E29: 01451152440673 | F29: =+Exp!L142 -> 0
B30: 29 | C30: Musisi Eric Njagala | E30: 1070011937104 | F30: =+Exp!L51 -> 0
B31: 30 | C31: Shirly Mukunde | E31: 1410014601484 | F31: =+Exp!L158 -> 0
B32: 31 | C32: Joshua Mujunga | E32: 01070014831027 | F32: =+Exp!L100 -> 0
B33: 32 | C33: Isaiah Ampumuza | E33: 01070015281562 | F33: =+Exp!L84 -> 0
B34: 33 | C34: Alex Ssentongo | E34: 227559200011 | F34: =+Exp!L19 -> 0
B35: 34 | C35: Lailah Nalukwata | E35: 0143099898523 | F35: =+Exp!L112 -> 0
B36: 35 | C36: Ahabu Bwesigye | E36: 01170015014825 | F36: =+Exp!L179 -> 0
B37: 36 | C37: Aaron Paul Odong | E37: 01490015297457 | F37: =+Exp!L141 -> 0
B38: 37 | C38: Sultan Buyungo Ahmed | E38: 01070012379118 | F38: =+Exp!L16 -> 0
B39: 38 | C39: Mark Agaba | E39: 01660011955368 | F39: =+Exp!L121 -> 0
B40: 39 | C40: Marvin Ndahura | E40: 01070015415899 | F40: =+Exp!L125 -> 0
...

Sheet Bank Salary
B1: NBS
B2: S/No. | C2: Name | D2: ST/REF. No. | E2: Saving Account No. | F2: Amount
B3: 1 | C3: Kaudha Mwasit | D3: 050147 | E3: 1013011661297 | F3: =+Salary!Q161 -> 0
B4: 2 | C4: Salmah Namwanje | D4: 050147 | E4: 1013011937394 | F4: =+Salary!Q190 -> 0
B5: 3 | C5: Semwogerere Derick | D5: 050147 | E5: 01073044211710 | F5: =+Salary!Q49 -> 0
B6: 4 | C6: Ibanda Samuel | D6: 050147 | E6: 01493014713209 | F6: =+Salary!Q191 -> 0
B7: 5 | C7: Richard Olwenyi | D7: 050147 | E7: 1151152915113 | F7: =+Salary!Q183 -> 0
B8: 6 | C8: Isaac Mubuka | D8: 050147 | E8: 01063089038015 | F8: =+Salary!Q99 -> 0
B9: 7 | C9: Joseph Mawanda | D9: 050147 | E9: 01063089095825 | F9: =+Salary!Q117 -> 0
B10: 8 | C10: Irene Constance Namajja | D10: 050147 | E10: 01063089069431 | F10: =+Salary!Q94 -> 0
B11: 9 | C11: Isima Isiko | D11: 050147 | E11: 01063089037812 | F11: =+Salary!Q103 -> 0
B12: 10 | C12: Katumba Moses | D12: 050147 | E12: 01513089227682 | F12: =+Salary!Q156 -> 0
B13: 11 | C13: Alex Mugasha | D13: 050147 | E13: 01081157877128 | F13: =+Salary!Q21 -> 0
B14: 12 | C14: Isaac otwii | D14: 050147 | E14: 01051154833026 | F14: =+Salary!Q100 -> 0
B15: 13 | C15: Brian Tukasingura | D15: 050147 | E15: 01421000215916 | F15: =+Salary!Q226 -> 0
B16: 14 | C16: Ayamo Ruth Eyobu | D16: 050147 | E16: 01081099698765 | F16: =+Salary!Q189 -> 0
B17: 15 | C17: Kyomu Henry | D17: 050147 | E17: 1063013376621 | F17: =+Salary!Q90 -> 0
B18: 16 | C18: Pheiona Nakatte | D18: 050147 | E18: 01490010829509 | F18: =+Salary!Q238 -> 0
B19: 17 | C19: Sarah Nabwami | D19: 050147 | E19: 01071159815335 | F19: =+Salary!Q240 -> 0
B20: 18 | C20: Henry Mugenyi | D20: 050147 | E20: 01070010802519 | F20: =+Salary!Q91 -> 0
B21: 19 | C21: Patricia Agaba | D21: 050147 | E21: 01070011977414 | F21: =+Salary!Q167 -> 0
B22: 20 | C22: Kitimbo Thomas | D22: 050147 | E22: 01440011974888 | F22: =+Salary!Q209 -> 0
B23: 21 | C23: Magembe Farish | D23: 050147 | E23: 01030012235582 | F23: =+Salary!Q65 -> 0
B24: 22 | C24: Kenneth Kaweesa | D24: 050147 | E24: 01060012126804 | F24: =+Salary!Q131 -> 0
B25: 23 | C25: Kiwanuka John Paul | D25: 050147 | E25: 01070012330676 | F25: =+Salary!Q115 -> 0
B26: 24 | C26: Simon Kaggwa Njala | D26: 050147 | E26: 01013010046204 | F26: =+Salary!Q262 -> 0
B27: 25 | C27: Joseph Omagor | D27: 050147 | E27: 01981131213490 | F27: =+Salary!Q118 -> 0
B28: 26 | C28: Agrey Waguma | D28: 050147 | E28: 01070014050534 | F28: =+Salary!Q16 -> 0
B29: 27 | C29: Wasswa Hassan Mutebi | D29: 050147 | E29: 01070010885253 | F29: =+Salary!Q87 -> 0
B30: 28 | C30: Dennis Ibanda | D30: 050147 | E30: 01070014676345 | F30: =+Salary!Q46 -> 0
B31: 29 | C31: Paul Kayonga | D31: 050147 | E31: 01451152440673 | F31: =+Salary!Q173 -> 0
B32: 30 | C32: Jamila Mulindwa Namuyiga | D32: 050147 | E32: 01010014546860 | F32: =+Salary!Q110 -> 0
B33: 31 | C33: Ssekanjako Patrick | D33: 050147 | E33: 01070012379057 | F33: =+Salary!Q171 -> 0
B34: 32 | C34: Musisi Eric Njagala | D34: 050147 | E34: 1070011937104 | F34: =+Salary!Q59 -> 0
B35: 33 | C35: Joshua Mujunga | D35: 050147 | E35: 01070014831027 | F35: =+Salary!Q123 -> 0
B36: 34 | C36: Malcom Ntambi | D36: 050147 | E36: 01070014765605 | F36: =+Salary!Q141 -> 0
B37: 35 | C37: Ahabu Bwesigye | D37: 050147 | E37: 01170015014825 | F37: =+Salary!Q222 -> 0
B38: 36 | C38: Mark Agaba | D38: 050147 | E38: 01660011955368 | F38: =+Salary!Q144 -> 0
B39: 37 | C39: Aaron Paul Odong | D39: 050147 | E39: 01490015297457 | F39: =+Salary!Q172 -> 0
B40: 38 | C40: Isaiah Ampumuza | D40: 050147 | E40: 01070015281562 | F40: =+Salary!Q102 -> 0
...
